<?xml version="1.0"?>
<robot name="simple_humanoid_arm">

  <!-- Base Link -->
  <link name="base_link">
    <visual>
      <geometry><box size="0.1 0.1 0.1"/></geometry>
      <material name="blue"><color rgba="0 0 0.8 1"/></material>
    </visual>
    <collision>
      <geometry><box size="0.1 0.1 0.1"/></geometry>
    </collision>
    <inertial>
      <mass value="0.1"/>
      <inertia ixx="0.0001" ixy="0" ixz="0" iyy="0.0001" iyz="0" izz="0.0001"/>
    </inertial>
  </link>

  <!-- Joint 1: Shoulder Pitch -->
  <joint name="shoulder_pitch_joint" type="revolute">
    <parent link="base_link"/>
    <child link="upper_arm_link"/>
    <origin xyz="0 0 0.05" rpy="0 0 0"/>
    <axis xyz="0 1 0"/>
    <limit lower="-1.57" upper="1.57" effort="10" velocity="0.5"/>
  </joint>

  <!-- Link 2: Upper Arm -->
  <link name="upper_arm_link">
    <visual>
      <geometry><cylinder radius="0.02" length="0.2"/></geometry>
      <origin xyz="0 0 0.1" rpy="0 0 0"/>
      <material name="red"><color rgba="0.8 0 0 1"/></material>
    </visual>
    <collision>
      <geometry><cylinder radius="0.02" length="0.2"/></geometry>
      <origin xyz="0 0 0.1" rpy="0 0 0"/>
    </collision>
    <inertial>
      <mass value="0.2"/>
      <origin xyz="0 0 0.1" rpy="0 0 0"/>
      <inertia ixx="0.001" ixy="0" ixz="0" iyy="0.001" iyz="0" izz="0.0001"/>
    </inertial>
  </link>

  <!-- Joint 2: Elbow Yaw -->
  <joint name="elbow_yaw_joint" type="revolute">
    <parent link="upper_arm_link"/>
    <child link="forearm_link"/>
    <origin xyz="0 0 0.2" rpy="0 0 0"/>
    <axis xyz="0 0 1"/>
    <limit lower="-1.57" upper="1.57" effort="10" velocity="0.5"/>
  </joint>

  <!-- Link 3: Forearm -->
  <link name="forearm_link">
    <visual>
      <geometry><cylinder radius="0.015" length="0.15"/></geometry>
      <origin xyz="0 0 0.075" rpy="0 0 0"/>
      <material name="green"><color rgba="0 0.8 0 1"/></material>
    </visual>
    <collision>
      <geometry><cylinder radius="0.015" length="0.15"/></geometry>
      <origin xyz="0 0 0.075" rpy="0 0 0"/>
    </collision>
    <inertial>
      <mass value="0.15"/>
      <origin xyz="0 0 0.075" rpy="0 0 0"/>
      <inertia ixx="0.0005" ixy="0" ixz="0" iyy="0.0005" iyz="0" izz="0.00005"/>
    </inertial>
  </link>

  <material name="blue"/>
  <material name="red"/>
  <material name="green"/>

</robot>
